Workbook

Sheet RATIO
K2: Standort | L2: (Alle)
K3: Verantwortlich | L3: (Alle)
K5: Count | L5: Prio
K6: Zeilenbeschriftungen | L6: Hoch | M6: Mittel | N6: Kritisch | O6: Niedrig | P6: (Leer) | Q6: Gesamtergebnis
K7: Offen | L7: 35 | M7: 17 | N7: 2 | O7: 1 | P7: 2 | Q7: 57
K8: Major NC | L8: 9 | M8: 1 | N8: 2 | Q8: 12
K9: Minor NC | L9: 15 | M9: 14 | P9: 1 | Q9: 30
K10: Observation | L10: 10 | M10: 2 | O10: 1 | P10: 1 | Q10: 14
K11: (Leer) | L11: 1 | Q11: 1
K12: (Leer) | L12: 1 | P12: 1 | Q12: 2
K13: Major NC | L13: 1 | Q13: 1
K14: Observation | P14: 1 | Q14: 1
K15: In Bearbeitung | L15: 2 | Q15: 2
K16: Minor NC | L16: 2 | Q16: 2
K17: Gesamtergebnis | L17: 38 | M17: 17 | N17: 2 | O17: 1 | P17: 3 | Q17: 61

Sheet TISAX Finding Register
A1: Finding-ID | B1: ISA Modul | C1: Kapitel | D1: Kontroll-Nr. | E1: Kontrollfrage (EN) | F1: Kontrollfrage (DE) | G1: Finding-Typ | H1: Finding-Beschreibung | I1: Reifegrad IST (0-5) | J1: Reifegrad SOLL | K1: Gap | L1: Maßnahme | M1: Umsetzungsgegenstand, Prozessbezug und Workflow Items | N1: X-Referenzen zu StageReview Findings | O1: Complete Remediation Scope | P1: Verantwortlich | Q1: Standort | R1: Priorität | S1: Status | T1: Frist | U1: Nachweis / Link | V1: ISB-Kommentar | W1: Ct.
A2: F-General | B2: General Evidence in Catalogue | C2: General | E2: Automotive treatment by OEM | F2: Automotive treatment by OEM | G2: Observation | H2: Die OEM´s versuchen Ihre Lieferanten auszusortieren, über diesen (TISAX) Vorwand, kommt auf die Auswahl an alternativen Lieferanten an. Wenn Preis gleich ist oder wenn ersetzbar. Wenn schwer ersatzbar dann ist TISAX wieder wichtig. | K2: =IF(AND(ISNUMBER(I2),ISNUMBER(J2)),J2-I2,"") | L2: Awareness Sales und KAMs | M2: Umsetzungsgegenstand: Awareness Sales und KAMs | N2: Vorgelagert (Voraussetzung): - keine (eigenständige Lessons-Learned-Auswertung) Nachgelagert (liefert Input an): - Row 31 / F-013 / 1.6.1 (Incident Meldewesen) - Row 33 / F-015 / 1.6.3 (Krisen-/BCM) - Row 49 / F-031 / 5.2.3 (Malware-Schutz) - Row 50 / F-032 / 5.2.4 (Logging/Eventprot.) - Row 54 / F-036 / 5.2.8 (BCM/DR-Tests) Querverweise: - Row 32 / F-014 / 1.6.2 (OEM-Kommunikation) - Row 6 / F-General/Major NC (Wirksamkeit ML3) | P2: Sales Hubertus Linz | Q2: Alle | R2: Mittel | S2: Offen | T2: 46142 | W2: 1
A3: F-General | B3: General Evidence in Catalogue | C3: Row "E" more details for the "how" of the implementation description | E3: To what extent are information security policies available? | F3: Inwieweit sind Informationssicherheitsrichtlinien verfügbar? | G3: Observation | H3: Row E to be extended | K3: =IF(AND(ISNUMBER(I3),ISNUMBER(J3)),J3-I3,"") | L3: Klare Definition Richtlinie zur Dokumentenlenkung, Terminologie für Dateinamen, wer ist verantwortlich für Richtlinie (Einkauf, IT, etc.) -> Dokumentenlenkungsrichtlinie Überprüfungsdatum muss ersichtlich sein. Ist der Verantwortliche sichtbar im BOS. Vorlage für Policy. -> Wie werden Richtlinien erstellt , wer die Verantwortung dafür hat, Namenskonventionen und Freigabeprozess. -> Prüfung ob der Prozess- bzw. Dokumentenverantwortliche im BOS genannt und ersichtlich ist. -> Prozess wie BOS sich verhält, wenn der jährliche Review nicht erfolgt ist (Policy Bestandteil). | M3: Umsetzungsgegenstand: Verbindliche Dokumentenlenkungsrichtlinie als Top-Level-Vorgabe für das gesamte ISMS-Policy-Framework (Namenskonvention, Versionierung, Approval, Review-Zyklus, Eigentümer/Reviewer). Prozessbezug: VDA ISA 1.1.1; ISO 27001 Clause 7.5 (dokumentierte Information); BOS/ISM in QBD.net. Workflow Items: 1. Erstellung Richtlinie Dokumentenlenkung (Owner: ISB) inkl. Klassifizierungsfeld und 12-Monats-Review. 2. BOS-Steckbrief je Policy mit sichtbarem Dokumenten- und Prozessverantwortlichen. 3. BOS-Eskalations-Workflow bei nicht erfolgtem Jahres-Review. Nachweis: Richtlinie freigegeben, Stichprobe Policy-Liste mit Reviewdatum, BOS-Reportauszug. Abhängigkeiten (Detail s. Spalte N): → methodisches Cross-Cutting für alle Findings | N3: Vorgelagert: - keine (methodisches Catalogue-Finding) Nachgelagert: - ALLE Findings (Catalogue-Pflege betrifft alle Module) Querverweise: - Row 4 / F-General (Unternehmensgrößen-Anpassung) - Row 5 / F-General (Catalogue Row F) | O3: Policy Framework: - ISMS-Dokumentenstrategie (Master-Dokumentenliste) Standards/Leitfäden: - VDA ISA 6.0.3 Anwendungsleitfaden (ENX) - ENX Assessment Guidance (aktuelle Version) Weitere Empfehlungen: - Catalogue-Pflege-Prozess als Audit-Pre-Check etablieren - Nachweispfade zentral in ISMS-Tool (z. B. SharePoint-Library) referenzieren - Auditor-Kommunikation: Catalogue-Updates protokollieren | P3: Roland Walter | Q3: Alle | R3: Hoch | S3: Offen | T3: 46142 | W3: 1
A4: F-General | B4: General Evidence in Catalogue | C4: General | E4: Unternehmensgrößen irrelevant | F4: Dem Unternehmen angemessen” gibt es nicht. | G4: Observation | H4: Unternehmensgröße wird nicht berücksichtigt. Wenn du AL3 willst musst du die Kontrollfragen beantworten. “ | L4: Keine Ausnahmen bei Wirksamkeitsnachweisen aufgrund Belegschaftsgröße bzw. Unternehmensgröße. | M4: Umsetzungsgegenstand: Verzicht auf Ausnahme-Argumentation aufgrund Unternehmensgröße; vollständige Erfüllung aller VDA-ISA-Kontrollen im AL3-Scope mit dokumentierter Risiko-Begründung bei Nicht-Anwendbarkeit. Prozessbezug: VDA ISA 6.0.3 Methodik AL3; ENX-Prüfvorgaben; SoA-Logik ISO 27001 Clause 6.1.3. Workflow Items: 1. SoA-Review (Owner: ISB): jede 'n/a'-Markierung mit dokumentierter Risikobegründung. 2. Briefing aller Maßnahmenverantwortlichen: keine Größenargumente in Auditgesprächen. Nachweis: SoA mit vollständiger Begründungstabelle, Trainingsnachweis. Abhängigkeiten (Detail s. Spalte N): → definiert AL3-Niveau für ALLE Findings | N4: Vorgelagert: - keine Nachgelagert: - ALLE Findings mit AL3-Reifegrad-Erwartung (Ist-Bewertung) | O4: Policy Framework: - Statement of Applicability (SoA) mit AL3-Begründung je Control - ISMS-Scope-Dokument inkl. Unternehmensgrößen-Argumentation Standards: - VDA ISA 6.0.3 Maturity Model (ML 0–5) - ENX Simplified Group Assessment (SGA) Guidance - ISO/IEC 27001:2022 §4.3 Scope Weitere Empfehlungen: - Hybrid-Assessment-Strategie (SGA + individuell) dokumentieren - Maturity-Gap-Analyse je Standort mit Ziel ML 2,5 - Auditor-Frühabstimmung zur AL3-Erwartungshaltung pro Werk | P4: Alle | Q4: Alle | R4: Hoch
A5: F-General | B5: Catalogue Row F | C5: Row "F" must include document name, version and date. | E5: To what extent are information security policies available? | F5: Inwieweit sind Informationssicherheitsrichtlinien verfügbar? | G5: Observation | H5: Row "F" must include document name, version and date. | J5: 3 | L5: Bei F darauf achten das die Version und den Dokumentennamen + Datum in der excel ersichtlich ist | M5: Umsetzungsgegenstand: Sicherstellung, dass in der ISA-Excel (Spalte F – Implementation) zu jeder Kontrolle Dokumentname, Versionsnummer und Datum vollständig benannt sind. Prozessbezug: VDA ISA 6.0.3 Antwortmethodik (Catalogue Row F); ENX-Audit-Format. Workflow Items: 1. ISA-Excel pro Standort prüfen (Owner: ISB), Vollständigkeit Dokname/Version/Datum. 2. Standardformatvorgabe an alle Verantwortlichen kommunizieren. Nachweis: vollständig befüllte ISA-Spalte F, Stichprobenprotokoll. Abhängigkeiten (Detail s. Spalte N): → baut auf F-001/1.1.1; betrifft Spalte S aller Findings | N5: Vorgelagert: - Row 7 / F-001 / 1.1.1 (Dokumentenlenkungs-RL liefert Versionierung) Nachgelagert: - ALLE Findings (Spalte S Nachweis/Link muss Dokumentenkopf erfüllen) | O5: Policy Framework: - RL Dokumentenlenkung mit verpflichtenden Metadaten (Name, Version, Datum, Klassifikation, Eigentümer) - Dokumentenkopf-Vorlage (REUTIB-Corporate-Design) Standards: - ISO/IEC 27001:2022 A.5.1, A.5.37 - ISO 9001:2015 §7.5 (Dokumentierte Information) - VDA ISA 6.0.3 Kap. 1.1.1 Weitere Empfehlungen: - Document-Owner-Liste mit Review-Zyklus im ISMS-Tool - Catalogue-Audit: Stichprobe 20 % aller Policies pro Quartal | W5: 1
A6: F-General | B6: Control Verification | C6: All Kapitel | E6: To what extent are information security policies available? | F6: Inwieweit sind Informationssicherheitsrichtlinien verfügbar? | G6: Major NC | H6: Implementation of workflows and evidences of training and enforcements | J6: 3 | L6: No Training, no enforcement of process according to control no Maturity Level 3 | M6: Umsetzungsgegenstand: Aufbau eines verbindlichen Trainings- und Enforcement-Verfahrens je Richtlinie/Standard als Kern-AL3-Voraussetzung — Reifegrad 3 setzt dokumentierte und nachweisbare Durchsetzung voraus. Prozessbezug: VDA ISA-Reifegradlogik (Level 3 'etabliert'); ISO 27001 Clause 7.2/7.3; VDA ISA 2.1.3 (Awareness & Training). Workflow Items: 1. Verknüpfung TTT-Konzept mit Policy-Framework (Owner: ISB + HR). 2. Schulungsmatrix Richtlinie × Zielgruppe × Standort × Sprache. 3. Wirksamkeits-Stichproben (Phishing-Simulation, Walkthrough-Tests). 4. Internes Auditprogramm integriert. Nachweis: Trainingsregister je MA, Stichprobenprotokoll, Audit-Berichte. Abhängigkeiten (Detail s. Spalte N): → zwingend vor ML3: F-001, F-002, F-011, F-018 | N6: Vorgelagert (zwingend für ML3): - Row 7-9 / F-001 / 1.1.1 (Policy Framework) - Row 29 / F-011 / 1.5.1 (KPIs / Wirksamkeit) - Row 12 / F-002 / 1.2.1 (KPI-Definition) Nachgelagert: - Row 36 / F-018 / 2.1.3 (TTT-Schulungskonzept) - ALLE Findings (Workflow-Nachweise pro Owner) Querverweise: - Row 4 / F-General (AL3-Niveau) - Row 30 / F-012 / 1.5.2 (Independent Review) | O6: Policy Framework: - Master-Schulungs- und Awareness-Konzept (TTT) - RL Wirksamkeitsmessung & ISMS-KPIs - Approval-Workflow-Matrix (RACI je Prozess) Standards: - ISO/IEC 27001:2022 §7.2 (Kompetenz), §7.3 (Awareness), §9.1 (Monitoring) - ISO/IEC 27004 (ISMS-Metriken) - VDA ISA 6.0.3 Kap. 1.5.1 (Wirksamkeit) Regulatorisch: - NIS-2 Art. 20(2) Schulungspflicht Leitung - NIS-2 Art. 21(2)(g) Cyberhygiene & Schulung Weitere Empfehlungen: - Vor AL3-Hauptaudit: Workflow-Walkthrough mit allen Process Ownern - Trainings-KPI: Abdeckungsgrad ≥ 95 % je Standort - TTT-C-Level-Approval-Meeting (30 Min) priorisieren — Vorbedingung für ML3 | Q6: Alle | R6: Hoch | W6: 1
A7: F-001 | B7: Information Security | C7: IS Policies and Organization | D7: 1.1.1 | E7: To what extent are information security policies available? | F7: Inwieweit sind Informationssicherheitsrichtlinien verfügbar? | G7: Minor NC | H7: Anforderung Erstellung BOS/ISM Dokumentenlenkungsrichtlinie | I7: 2 | J7: 3 | K7: =IF(AND(ISNUMBER(I7),ISNUMBER(J7)),J7-I7,"") -> 1 | L7: Erstellung einer Richtlinie zur Dokumentenlenkung im CAQ QBD.net (BOS/ISM), inklusive Terminologie für Dateinamen, wie auch der Regelungen der Verantwortlichkeiten im BOS/ISM Kontext, | M7: Umsetzungsgegenstand: Dokumentenlenkungsrichtlinie für BOS/ISM-Dokumente in CAQ QBD.net (Namenskonvention, Klassifizierung, Approval, Review, Archivierung). Prozessbezug: VDA ISA 1.1.1; ISO 27001 A.5.1 + Clause 7.5; BOS/ISM-Governance. Workflow Items: 1. RL-Entwurf (Owner: ISB). 2. Review im BOS/ISMS-Coordination-Meeting. 3. Freigabe GL. 4. Roll-out + Awareness DE/AT/SK/PL. Nachweis: RL v1.0 in QBD.net, Trainingsnachweis, BOS-Eintrag. Abhängigkeiten (Detail s. Spalte N): → Fundament: Voraussetzung für ALLE Policy-Findings | N7: Vorgelagert: - keine (Fundamentbaustein) Nachgelagert (Voraussetzung für): Gegenprüfung für Anwendbarkeit und Verantwortung benannter QS-Engineers bzw. Responsbies in den Standorten. | O7: Policy Framework: - Master-RL Dokumentenlenkung BOS/ISMS - Verbindliche Metadaten: Titel, Version, Datum, Owner, Klassifikation, Freigabe - Dokumentenstruktur-Pyramide (RL → Verfahrensanweisung → Arbeitsanweisung → Formular) Standards: - ISO/IEC 27001:2022 A.5.1, A.5.37 - ISO 9001:2015 §7.5 - VDA ISA 6.0.3 Kap. 1.1.1 Weitere Empfehlungen: - Dokumentenmanagementsystem (z. B. SharePoint/M-Files) als Single Source - Versionshistorie & Approval-Workflow elektronisch (revisionssicher) - 4-sprachige Verfügbarkeit DE/EN/SK/PL für relevante Top-Level-RL | P7: Roland Walter | Q7: Alle | R7: Hoch | S7: In Bearbeitung | T7: 46142 | W7: 1
A8: F-001 | B8: Information Security | C8: IS Policies and Organization | D8: 1.1.1 | E8: To what extent are information security policies available? | F8: Inwieweit sind Informationssicherheitsrichtlinien verfügbar? | G8: Minor NC | H8: Überprüfungsdatum muss ersichtlich sein | I8: 2 | J8: 3 | K8: =IF(AND(ISNUMBER(I8),ISNUMBER(J8)),J8-I8,"") -> 1 | L8: Nachprüfung und Ergänzung Reviewdatum muss in der Policy nach Approval sichtbar sein. | M8: Umsetzungsgegenstand: Sichtbarmachung des Review- und Approval-Datums in der Kopfzeile jeder Policy nach Freigabe. Prozessbezug: VDA ISA 1.1.1; Dokumentenlenkungsrichtlinie (Bezug F-001/Row 7). Workflow Items: 1. Policy-Template anpassen (Felder: letzte Review, nächste Review, Approver, Approval-Datum) — Owner: ISB. 2. Nacharbeit aller Bestandsdokumente. 3. BOS-Reporting Liste aller RL mit Review-Daten. Nachweis: Sample-Audit 5 RL, BOS-Reportauszug. Abhängigkeiten (Detail s. Spalte N): → baut auf F-001/1.1.1 | N8: Vorgelagert: - Row 7 / F-001 / 1.1.1 (Dokumentenlenkungs-RL) Nachgelagert: - ALLE Policies/Verfahrensanweisungen (Review-Pflicht) Querverweise: - Row 5 / F-General (Catalogue-Metadaten) | O8: Policy Framework: - Review-Zyklen-Matrix: Top-Level-RL jährlich, Verfahrensanweisungen 2-jährlich, anlassbezogen ad hoc - Review-Trigger: Gesetzesänderung, Vorfall, Audit-Finding, Org-Änderung Standards: - ISO/IEC 27001:2022 A.5.1.2 (Review of policies) - ISO 9001:2015 §7.5.3 Weitere Empfehlungen: - Automatisierte Erinnerungen 60/30/14 Tage vor Review-Datum - Review-Protokoll als Pflichtnachweis (auch bei 'no changes') - Quartalsbericht 'überfällige Reviews' an CIO/Geschäftsleitung | P8: Mark Lütz | Q8: Alle | R8: Hoch | S8: In Bearbeitung | T8: 46142 | W8: 1
A9: F-001 | B9: Information Security | C9: IS Policies and Organization | D9: 1.1.1 | E9: To what extent are information security policies available? | F9: Inwieweit sind Informationssicherheitsrichtlinien verfügbar? | G9: Minor NC | H9: Alle Policies in der Klassifizierung auf "Intern" umstellen. | I9: 2 | J9: 3 | K9: =IF(AND(ISNUMBER(I9),ISNUMBER(J9)),J9-I9,"") -> 1 | L9: Umstellung Klassifizierung auf "Intern". | M9: Umsetzungsgegenstand: Vereinheitlichung der Dokumentenklassifizierung aller internen Richtlinien auf 'Intern' gem. Klassifizierungsschema. Prozessbezug: VDA ISA 1.1.1; Asset-Mgmt.- und Klassifizierungs-Policy; ISO 27001 A.5.12/A.5.13. Workflow Items: 1. Bestandsaufnahme aller Policies (Owner: ISB) und Klassifizierungsstatus. 2. Bulk-Anpassung Klassifizierung 'Intern' in QBD.net. 3. Aktualisierung Template-Standard. Nachweis: Klassifizierungs-Auditliste, QBD.net-Reportauszug. Abhängigkeiten (Detail s. Spalte N): → baut auf F-001 + F-010; nachgelagert F-028 | N9: Vorgelagert: - Row 7 / F-001 / 1.1.1 (Dokumentenlenkungs-RL) - Row 28 / F-010 / 1.4.1 (Klassifizierungsschema) Nachgelagert: - ALLE Policies (einheitliche Klassifikation) - Row 46 / F-028 / 5.1.2 (Verschlüsselung je Klasse) Querverweise: - Row 42 / F-024 / 4.1.2 (MFA je Klassifikation) | O9: Policy Framework: - RL Informationsklassifizierung mit 4 Stufen: Öffentlich / Intern / Vertraulich / Streng vertraulich - OEM-spezifisches Mapping ('Strictly Confidential' = Streng vertraulich) Standards: - ISO/IEC 27001:2022 A.5.12, A.5.13 - VDA ISA 6.0.3 Kap. 1.4.1 - VDA Prototypenschutz-Leitfaden Weitere Empfehlungen: - Dokumentenkopf-Vorlage mit Klassifikations-Stempel - DLP-Policy verknüpft mit Klassifikation (M365 Sensitivity Labels) - Schulungs-Modul Klassifikation als Pflichtschulung (TTT-Phase 2) | P9: Mark Lütz | Q9: Alle | R9: Hoch | S9: Offen | T9: 46142 | W9: 1
A10: F-002 | B10: Information Security | C10: IS Policies and Organization | D10: 1.2.1 | E10: To what extent is information security managed within the organization? | F10: Inwieweit wird die Informationssicherheit innerhalb der Organisation verwaltet? | G10: Major NC | H10: Security Incident Response Mgmt. | I10: 2 | J10: 3 | K10: =IF(AND(ISNUMBER(I10),ISNUMBER(J10)),J10-I10,"") -> 1 | L10: Was sind "Safety & Security Vorfälle", aktuell gibt es keine Beschreibung. Aufnahme Meldekette und entspr. Saftey & Sec. Incident Mailbox. Anpassung PROC für Prozessimplementierung, POL anpassen (inkl. Beispiele), Guideline aufbauen und STD für die entspr. Bereiche, inkl. Trainings in den Sprachversionen. | M10: Umsetzungsgegenstand: Vollständige Etablierung Information-Security-Incident-Response: Definition Sicherheitsereignis vs. Sicherheitsvorfall, Meldekette, zentrale Mailbox, Sprachversionen, Trainings. Prozessbezug: VDA ISA 1.2.1 + 1.6.1/1.6.2; ISO 27001 A.5.24–A.5.28; NIS-2 Art. 23 (Meldepflichten). Workflow Items: 1. RL Incident Response (Owner: ISB) mit definierten Begriffen. 2. Aufbau STD Meldekette + zentrale Mailbox security-incident@reutib.com. 3. PROC-Anpassung für IT/OT/Facility/Krisenstab. 4. Trainings DE/EN/SK/PL inkl. OT-Schichtleiter. Nachweis: RL/STD/PROC freigegeben, Trainingsnachweise, Live-Tickets als Wirksamkeit. Abhängigkeiten (Detail s. Spalte N): → Major NC; baut auf F-001 + F-010; treibt F-013/F-014/F-015 | N10: Vorgelagert: - Row 7 / F-001 / 1.1.1 (Doku-Lenkung) - Row 28 / F-010 / 1.4.1 (Risiko-Framework) Nachgelagert (entfaltet sich in): - Row 31 / F-013 / 1.6.1 (Incident Meldewesen) - Row 32 / F-014 / 1.6.2 (OEM-Kommunikation) - Row 33 / F-015 / 1.6.3 (Krise/BCM) Querverweise: - Row 2 / F-General (Play-Ransomware Lessons-Learned) - Row 49 / F-031 / 5.2.3 (Malware) - Row 50 / F-032 / 5.2.4 (Logging als Detektion) | O10: Policy Framework: - RL Incident Response & Security Operations - IR-Playbooks (Ransomware, Phishing, Data Breach, OT-Incident) - SOC-Runbook für 24/7-Reaktion (extern oder intern) Standards: - ISO/IEC 27001:2022 A.5.24-A.5.28 - ISO/IEC 27035-1/-2 (Incident Mgmt Lifecycle) - NIST SP 800-61r2 (Computer Security Incident Handling) - VDA ISA 6.0.3 Kap. 1.2.1 / 1.6.x Regulatorisch: - NIS-2 Art. 21(2)(c), Art. 23 (Meldepflicht) - DSGVO Art. 33, 34 (Datenschutzvorfälle) Weitere Empfehlungen: - Major NC: Vorbereitung Wirksamkeitsnachweis mit Sophos-XDR-Auswertung - Eskalations-Matrix mit OEM-Kontakten je Werk - Tabletop-Übung 2026 vor Hauptaudit | P10: ISB, IT, GL | Q10: Alle | R10: Hoch | S10: Offen | T10: 46157 | W10: 1
A11: F-002 | B11: Information Security | C11: IS Policies and Organization | D11: 1.2.1 | E11: To what extent is information security managed within the organization? | F11: Inwieweit wird die Informationssicherheit innerhalb der Organisation verwaltet? | G11: Major NC | H11: Audit Programm u. Verantwortlichkeiten fehlen. | I11: 2 | J11: 3 | K11: =IF(AND(ISNUMBER(I11),ISNUMBER(J11)),J11-I11,"") -> 1 | L11: Internes Auditprogramm, wann , wer und wo definiert. | M11: Umsetzungsgegenstand: Internes ISMS-Auditprogramm (3-Jahres-Plan) mit definierten Auditzeitpunkten, Auditorenpool, Auditbereichen und Berichtswesen. Prozessbezug: VDA ISA 1.2.1 + 1.5.2; ISO 27001 Clause 9.2. Workflow Items: 1. 3-Jahres-Auditplan (Owner: ISB). 2. Auditorenpool (intern + unabhängig) etablieren. 3. Audit-Programm-Richtlinie freigeben (GL). 4. Erste interne Audits DE-Leutenbach und AT-Bischofshofen. Nachweis: Auditplan, Auditberichte, Management-Review-Input. Abhängigkeiten (Detail s. Spalte N): → Major NC; liefert Input an F-011 (1.5.1) und F-012 (1.5.2) | N11: Vorgelagert: - Row 7 / F-001 / 1.1.1 (Doku-Lenkung) - Row 16 / F-003 / 1.2.2 (ISB-Organigramm) Nachgelagert: - Row 29 / F-011 / 1.5.1 (Wirksamkeitsnachweise) - Row 30 / F-012 / 1.5.2 (Independent ISMS Review) - Row 50 / F-032 / 5.2.4 (Logging als Audit-Quelle) Querverweise: - Row 12 / F-002 / 1.2.1 (KPIs) | O11: Policy Framework: - RL Internes Audit & Management Review - Jahres-Auditprogramm 2026/2027 (rollierender 3-Jahres-Plan) - Audit-Charter (Unabhängigkeit, Berichtsweg an Geschäftsleitung) Standards: - ISO/IEC 27001:2022 §9.2 (Internal Audit), §9.3 (Management Review) - ISO 19011:2018 (Audit-Leitfaden) - VDA ISA 6.0.3 Kap. 1.2.1 Weitere Empfehlungen: - Lead Auditor-Qualifikation für 1 Person je Standort - Audit-Plan inkl. OT-Werke SK/PL/AT mit IEC-62443-Fokus - Audit-Findings-Tracker mit CAPA-Workflow (PDCA) | P11: Mark Lütz | Q11: Alle | R11: Mittel | S11: Offen | T11: 46157 | W11: 1
A12: F-002 | B12: Information Security | C12: IS Policies and Organization | D12: 1.2.1 | E12: To what extent is information security managed within the organization? | F12: Inwieweit wird die Informationssicherheit innerhalb der Organisation verwaltet? | G12: Minor NC | H12: Fehlende KPIs, Bewertung in der Label Abhängigkeit wo für die Controls notwendig.Nachweis fehlt für Assessment bzgl. Anwendbarkeit der Labels. | I12: 2 | J12: 3 | K12: =IF(AND(ISNUMBER(I12),ISNUMBER(J12)),J12-I12,"") -> 1 | L12: Siehe ISMS Policy in Punkt 5.2 "Stelle mir dar, dass Du alle Control-No betrachtet hast bzgl. Confidentail u. Very High Availability, Wichtig !: Trennung von Scorecard. Scorecard link oder doc von Patrick G. an Mark -> Mark erarbeitet KPI Dashboard für ISMS, Erzeugung Assessment Dokuments in der jährlichen Betrachtung. | M12: Umsetzungsgegenstand: ISMS-KPI-/KRI-Dashboard mit expliziter Label-Abhängigkeit (Confidential, Very High Availability) und Nachweis vollständiger Kontrollbetrachtung im jährlichen Assessment. Prozessbezug: VDA ISA 1.2.1; ISO 27001 Clause 9.1; Scorecard-Ableitung (Patrick G. → Mark Lütz). Workflow Items: 1. KPI-Set definieren (Owner: ISB) — Awareness-Quote, MTTD/MTTR, Patch-Compliance, BCM-Testrate, Lieferantenbewertungs-Quote. 2. Assessment-Dokument pro Label (C / Very High A). 3. Jährliche Wirksamkeitsbewertung als ISMS-Audit-Eingangsdokument. Nachweis: KPI-Dashboard, Assessment-Dokument, Management-Review-Protokoll. Abhängigkeiten (Detail s. Spalte N): → baut auf F-002 (Audit); Voraussetzung für F-011/F-012 + alle KPI-basierten Findings | N12: Vorgelagert: - Row 11 / F-002 / 1.2.1 (Auditprogramm) - Row 4 / F-General (AL3-Niveau) Nachgelagert: - Row 29 / F-011 / 1.5.1 (Wirksamkeit benötigt KPIs) - Row 30 / F-012 / 1.5.2 (Review benötigt KPIs) - Row 36 / F-018 / 2.1.3 (Schulungs-KPIs) - Row 50 / F-032 / 5.2.4 (Logging-KPIs) - Row 51 / F-033 / 5.2.5 (Patch-KPIs) Querverweise: - Row 6 / F-General (Workflow-KPIs) | O12: Policy Framework: - RL Wirksamkeitsmessung & ISMS-Kennzahlen - KPI-Katalog je VDA-ISA-Kapitel (Label-spezifisch: IS / Prototyp / Personenbez.) - ISMS-Cockpit (Power BI / Excel-Dashboard) mit Monats-Reporting Standards: - ISO/IEC 27001:2022 §9.1 (Monitoring) - ISO/IEC 27004 (ISMS-Metriken) - VDA ISA 6.0.3 Kap. 1.5.1 (für ML3 verbindlich) Weitere Empfehlungen: - Mindest-KPI-Set: Patch-Compliance, MFA-Coverage, Schulungs-Abdeckung, MTTR, Phishing-Klickrate, Vendor-Risk-Score - Label-Anwendbarkeitsmatrix als Anhang zum SoA - Quartals-Reporting an Geschäftsleitung als Wirksamkeitsnachweis | P12: Mark Lütz | Q12: Alle | R12: Mittel | S12: Offen | T12: 46157 | W12: 1
A13: F-003 | B13: Information Security | C13: IS Policies and Organization | D13: 1.2.2 | E13: To what extent are information security responsibilities organized? | F13: Inwieweit sind Informationssicherheitsaufgaben organisiert? | G13: Minor NC | H13: Fehlende Verantwortlichkeiten in OT SK/PL und Qualitfikationsnachweise in OT/PROD. | I13: 2 | J13: 3 | K13: =IF(AND(ISNUMBER(I13),ISNUMBER(J13)),J13-I13,"") -> 1 | L13: Wie sind die Verantworlichkeiten und die Kenntnisstände in der Produktoin definiert? Gibt es ein Dokument wo auch patches updates im OT berreich definiert sind? . Produktionsupdates, sicherheitslücken, gibt es backups, wurde das getestet Direkte Darstellung der Verantwortlichkeiten, Dokument: OT Seite zwingend erweitern für Produktionslinien in SK/PL Empfehlung für Training: Vorfallsbezogen agieren in OT | M13: Umsetzungsgegenstand: Definition und Dokumentation der IS-Verantwortlichkeiten und Qualifikationen im OT/Produktionsbereich, insbesondere für SK (Myjava) und PL (Międzyrzecze Górne). Prozessbezug: VDA ISA 1.2.2; IEC 62443-2-1 (Organisation und Verantwortlichkeiten im IACS); ISO 27001 A.5.2/A.5.3. Workflow Items: 1. RACI-Matrix OT-IS pro Standort (Owner: ISB + Plant Manager). 2. HR-Qualifikationsmatrix erweitern um OT-IS-Kompetenzen. 3. Patching-/Update-Verantwortlichkeiten OT dokumentieren. 4. Vorfallsbezogenes OT-Training (Schichtebene). Nachweis: RACI je Plant, Qualifikationsnachweise, OT-Verantwortlich-keits-RL. Abhängigkeiten (Detail s. Spalte N): → baut auf F-003 (Organigramm); treibt OT-Findings SK/PL | N13: Vorgelagert: - Row 16 / F-003 / 1.2.2 (ISB-Organigramm) Nachgelagert: - Row 14 / F-003 / 1.2.2 (OT-Assetliste SK/PL) - Row 15 / F-003 / 1.2.2 (OT-Verträge) - Row 21 / F-005 / 1.2.4 (OLA IT/OT) - Row 26-27 / F-009 / 1.3.4 (OT-SW-Mgmt + IEC 62443) - ALLE OT-Findings (5.2.5, 5.2.6, 5.2.7) Querverweise: - Row 17 / F-003 / 1.2.2 (IS in Projekten — Major NC) | O13: Policy Framework: - RL Rollen & Verantwortlichkeiten (RACI-Matrix IT/OT/IS) - Stellenbeschreibung OT-Verantwortlicher je Werk - Schnittstellenbeschreibung IT ↔ OT ↔ Qualität Standards: - ISO/IEC 27001:2022 A.5.2 (Roles & Responsibilities) - IEC 62443-2-1 (Security Programm für OT-Asset-Owner) - VDA ISA 6.0.3 Kap. 1.2.2 Weitere Empfehlungen: - OT-Lead je Standort SK-Myjava / PL-Międzyrzecze nominieren - Quartals-Jour-Fixe IT/OT/IS-Triade - OT-Verantwortlichkeiten in lokalen Sprachen kommunizieren | P13: SK/PL, HR, GL, ISB, OT/PROD. | Q13: SK/PL | R13: Hoch | S13: Offen | T13: 46172 | W13: 1
A14: F-003 | B14: Information Security | C14: IS Policies and Organization | D14: 1.2.2 | E14: To what extent are information security responsibilities organized? | F14: Inwieweit sind Informationssicherheitsaufgaben organisiert? | G14: Minor NC | H14: Vorgegebene OT Assetliste SK/PL ist noch nicht ausgefüllt von MB/TD. Erweitern für Connectivity für IP-Traffic (warum, wohin, was, wer steuert)? | I14: 2 | J14: 3 | K14: =IF(AND(ISNUMBER(I14),ISNUMBER(J14)),J14-I14,"") -> 1 | L14: Vervollständigung OT Asseliste und Erweiterung um Connectivity | M14: Umsetzungsgegenstand: Vervollständigung der OT-Asset-Liste SK/PL inkl. IP-Connectivity-Attribute (Protokoll, Ziel, Owner, Steuerung, Klassifizierung). Prozessbezug: VDA ISA 1.2.2 + 1.3.1; IEC 62443-2-1 Asset Inventory; ISO 27001 A.5.9. Workflow Items: 1. Asset-Erhebung vor Ort (Owner: Plant Manager + OT-Lead SK/PL). 2. Schemaerweiterung: Protokoll, Ziel-IP, Owner, Klassifizierung, Patchstand. 3. Übernahme in Matrix42 oder dediziertes OT-Repository. Nachweis: Asset-Liste SK/PL vollständig, IP-Kommunikationsmatrix. Abhängigkeiten (Detail s. Spalte N): → baut auf F-003; Pflicht für SK/PL; treibt OT-Findings 5.2.x | N14: Vorgelagert: - Row 13 / F-003 / 1.2.2 (OT-Verantwortlichkeiten) - Row 23 / F-006 / 1.3.1 (Asset Mgmt-Methodik) Nachgelagert: - Row 51 / F-033 / 5.2.5 (OT-Vulnerability Mgmt) - Row 52 / F-034 / 5.2.6 (OT-Pentest) - Row 53 / F-035 / 5.2.7 (OT-Netzwerk-Zonierung) - Row 55 / F-037 / 5.2.9 (OT-Backup) - Row 26-27 / F-009 / 1.3.4 (OT-SW) Querverweise: - Row 47 / F-029 / 5.2.1 (OT-Change-Mgmt) | O14: Policy Framework: - OT-Asset-Inventarisierungs-Verfahrensanweisung - Klassifikation OT-Assets (Level 0-3 nach Purdue-Modell) Standards: - IEC 62443-2-1 §SP.04 (Asset Inventory) - IEC 62443-3-2 (Risk Assessment & Zone/Conduit-Modell) - ISO/IEC 27001:2022 A.5.9 - VDA ISA 6.0.3 Kap. 1.3.1 / 1.3.4 Weitere Empfehlungen: - Tool-Auswahl: passives OT-Discovery (z. B. Claroty, Nozomi, Tenable.ot) für SK/PL - OT-Asset-Liste in Matrix42 als getrennte CMDB-Sicht - Kritikalitäts-Tagging je Anlage (Produktionsausfall-Folgekosten) | P14: Mark Lütz (SK/PL -> OT/PROD) | Q14: SK/PL | R14: Hoch | S14: Offen | T14: 46172 | W14: 1
A15: F-003 | B15: Information Security | C15: IS Policies and Organization | D15: 1.2.2 | E15: To what extent are information security responsibilities organized? | F15: Inwieweit sind Informationssicherheitsaufgaben organisiert? | G15: Major NC | H15: Information Sec. Anforderungen an OT Verträge und Assessment; Brandmeldeanlage, KLIMA etc. | I15: 2 | J15: 3 | K15: =IF(AND(ISNUMBER(I15),ISNUMBER(J15)),J15-I15,"") -> 1 | L15: Prüfung der bestehenden Verträge OT (SK/PL) -> wie sehen die verträge im OT bereich aus. Hot stand by mit Siemens zum beispiel. Gibt es updates für sps und wer stellt sie zu verfügung und testet und implementiert. Asset Liste hier erforderlich für vertragliche Gegebenheiten. | M15: Umsetzungsgegenstand: Prüfung und Anpassung bestehender OT-Wartungs-/Service-Verträge (SPS-Hersteller, Klima, BMA) gegen IS-Anforderungen (Hot-Standby, Patch-Bereitstellung, Testing, Datenfluss). Prozessbezug: VDA ISA 1.2.2 + 6.1.1; ISO 27001 A.5.19–A.5.22 (Lieferantenbeziehungen). Workflow Items: 1. Vertrags-Inventur OT-Lieferanten SK/PL (Owner: Plant Manager + Einkauf + ISB). 2. IS-Clause-Set: NDA, Incident-Notify, Patch-SLA, Asset-Listenpflege. 3. Nachverhandlung kritischer Verträge (z. B. Siemens Hot-Standby). Nachweis: Vertragsregister, IS-Annex je Vertrag, ISRA-Eintrag bei Restrisiko. Abhängigkeiten (Detail s. Spalte N): → Major NC; baut auf F-003 + F-001; treibt F-005/F-042/F-043 | N15: Vorgelagert: - Row 14 / F-003 / 1.2.2 (OT-Assetliste) - Row 7 / F-001 / 1.1.1 (Vertragsvorlagen) Nachgelagert: - Row 21 / F-005 / 1.2.4 (OLA) - Row 22 / F-005 / 1.2.4 (externe OT-Zugriffe) - Row 60 / F-042 / 6.1.1 (Supplier-IS-Mgmt) - Row 61 / F-043 / 6.1.2 (NDA) Querverweise: - Row 25 / F-008 / 1.3.3 (Externe IT-Dienste) | O15: Policy Framework: - RL OT-Lieferanten & Wartungspartner mit IS-Mindestanforderungen - Pflicht-Anhang IS-Klauseln (Logging, Zugriff, Incident-Meldung, Subunternehmer) - OT-Lieferanten-Assessment-Fragebogen (vor Vertragsabschluss) Standards: - ISO/IEC 27001:2022 A.5.19-A.5.23 - IEC 62443-2-4 (Security Programm-Anforderungen an Dienstleister) - VDA ISA 6.0.3 Kap. 6.1.x Weitere Empfehlungen: - Major NC: Bestandsverträge OT-Wartung systematisch nachverhandeln - Vertrags-Tracking in Einkaufstool integrieren (Eskalation bei IS-Lücke) - Auditrecht beim Lieferanten als Pflichtklausel | P15: Mark Lütz (SK/PL -> OT/PROD) | Q15: SK/PL | R15: Hoch | S15: Offen | T15: 46172 | W15: 1
A16: F-003 | B16: Information Security | C16: IS Policies and Organization | D16: 1.2.2 | E16: To what extent are information security responsibilities organized? | F16: Inwieweit sind Informationssicherheitsaufgaben organisiert? | G16: Observation | H16: ISO Nicht im Organigramm enthalten | I16: 2 | J16: 3 | K16: =IF(AND(ISNUMBER(I16),ISNUMBER(J16)),J16-I16,"") -> 1 | L16: Gibt es ein Organigramm auf Gruppenebene und wer ist für dieses dokument verantwortlich? wo steht das? | M16: Umsetzungsgegenstand: Aufnahme der ISB-Funktion in das Gruppen-Organigramm mit klar zugewiesener Berichtslinie an die Geschäftsleitung. Prozessbezug: VDA ISA 1.2.1/1.2.2; ISO 27001 Clause 5.3 (Rollen und Verantwortlichkeiten). Workflow Items: 1. Anpassung Gruppen-Organigramm (Owner: HR + GL). 2. ISB-Rolle als gestrichelte Linie zu allen Standorten visualisieren. 3. Freigabe und Ablage im BOS. Nachweis: aktuelles Organigramm, BOS-Verlinkung. Abhängigkeiten (Detail s. Spalte N): → Voraussetzung für F-002, F-003 und ISB-Eskalation aller Findings | N16: Vorgelagert: - keine (Stellenbeschreibung/Org-Strukturthema) Nachgelagert: - Row 11 / F-002 / 1.2.1 (Audit-Berichtsweg via ISB) - Row 13 / F-003 / 1.2.2 (OT-Verantwortlichkeiten) - ALLE Findings (ISB-Eskalationspfad) Querverweise: - Row 30 / F-012 / 1.5.2 (Unabhängigkeit der Review) | O16: Policy Framework: - Aktualisiertes Organigramm Reutter Group inkl. ISB-Position - ISB-Stellenbeschreibung mit direktem Berichtsweg Geschäftsleitung - Schnittstellen-Charta IT / CIO / Geschäftsleitung Standards: - ISO/IEC 27001:2022 A.5.2, A.5.3, A.5.4 - VDA ISA 6.0.3 Kap. 1.2.2 Regulatorisch: - NIS-2 Art. 20 (Verantwortung Leitungsorgane) Weitere Empfehlungen: - ISB-Reporting-Linie unabhängig von CIO (zur Geschäftsleitung) - ISB-Vertretungsregelung schriftlich fixieren - Organigramm im Mitarbeiterportal sichtbar machen | P16: Mark Lütz (SK/PL -> OT/PROD) | Q16: SK/PL | R16: Hoch | S16: Offen | T16: 46157 | W16: 1
A17: F-003 | B17: Information Security | C17: IS Policies and Organization | D17: 1.2.2 | E17: To what extent are information security responsibilities organized? | F17: Inwieweit sind Informationssicherheitsaufgaben organisiert? | G17: Major NC | H17: Fehlende Betrachtung der Informationssicherheit in Projekten (Sales, Engineering (PLM) und Purchaising (Supply Chaing) -> Beispiel: Wir haben ein Projekt, Kunde schickt ein NDA. Wer kennt den Inhalt und wie kommt dieser zu den Projektmitarbeitern ←genauso! Erzeugung Projekt Policy (!) | I17: 2 | J17: 3 | K17: =IF(AND(ISNUMBER(I17),ISNUMBER(J17)),J17-I17,"") -> 1 | L17: Infromationssicherheit in Projekten ist eines der heißesten Themen → Da sind wir (schlecht) Punkt 1.2.3. Erwartung das die Projekte als Vertaulich eingestuft werden, was bedeutet das bei den Kunden Projekte? Wie lange müssen und wie lange dürfen wir Projektdaten aufbewahren? Wie händeln wir das und wo ist es definiert- Beispiel 3-6 Monaten nach Projekt muss garantiert sein das die Projektdaten nicht mehr zugänglich sind. Übergabeworkflow von Sales zum Projekt > Hier existiert schon etwas - Abfragen gem. Screenshot. Wir haben ein Projekt, Kunde schickt ein NDA. Wer kennt den Inhalt und wie kommt dieser zu den Projektmitarbeitern ←genauso! Übergabe der Kundeninformationen Kundenabmachungen wie z.b. NDA muss in einen übergabe WF. Selbes für Vertragsinformationen (Beispiel: dürfen später sublieferenten verwendet werden, wie bekommt das prokjekt so ein Vertragsinfomrationsteil mit) -> Siehe Ausschnitt aus Screenshot was die Auditoren erwarten bzw. was in der Regel im Kontext mit der AL3 Zert. zu Gesicht bekommen. -> Screenshot StageReview 20.4.26 Expectations | M17: Umsetzungsgegenstand: Etablierung einer Projekt-Informationssicherheits-Richtlinie inkl. Klassifizierung, NDA-Handling, Sales→Projekt-Übergabe-Workflow sowie Aufbewahrungs- und Löschfristen für Projektdaten (3–6 Monate nach Projektabschluss). Prozessbezug: VDA ISA 1.2.3 (IS in Projekten); ISO 27001 A.5.8; OEM-Vertragsanforderungen. Workflow Items: 1. RL Projekt-Informationssicherheit (Owner: ISB + PMO). 2. STD Sales→Projekt-Handover-WF mit Pflichtfeldern Klassifizierung, NDA-Status, Sublieferanten-Restriktionen. 3. STD Projekt-Closure mit Datenlöschungs-/Archivierungs-WF. 4. Trainings für Sales, Engineering, Purchaising. Nachweis: RL freigegeben, Handover-Templates, Closure-Protokolle, Trainingsnachweise. Abhängigkeiten (Detail s. Spalte N): → Major NC; baut auf F-001/F-010/F-043; treibt F-004 + F-038 | N17: Vorgelagert: - Row 7 / F-001 / 1.1.1 (Doku-Lenkung) - Row 28 / F-010 / 1.4.1 (Risiko-Mgmt) - Row 61 / F-043 / 6.1.2 (NDA-Lifecycle) Nachgelagert: - Row 18 / F-004 / 1.2.3 (Konsolidierung Projekt-IS-RL) - Row 56 / F-038 / 5.3.1 (IS in neuen Systemen) Querverweise: - Row 9 / F-001 / 1.1.1 (Klassifizierung Prototypendaten) - Row 60 / F-042 / 6.1.1 (Supplier) | O17: Policy Framework: - RL Informationssicherheit in Projekten (gilt für ALLE Projekttypen) - Projekt-Initiierungs-Checkliste mit IS-Risk-Assessment - NDA-Templates (intern/extern/OEM) revisionssicher Standards: - ISO/IEC 27001:2022 A.5.8 (IS im Projektmanagement) - ISO/IEC 27005 (Risiko-Mgmt-Methodik) - VDA Prototypenschutz-Leitfaden (Pflicht bei OEM-Entwicklungsprojekten) - VDA ISA 6.0.3 Kap. 1.2.2 / 1.2.3 Weitere Empfehlungen: - Major NC: NDA-Vorlage durch externe Kanzlei prüfen lassen (Rechtsverbindlichkeit DE/AT/SK/PL) - IS-Gate im Projekt-Phasenmodell (Stage-Gate-Reviews) - Schulung Projektleiter zur IS-Risk-Assessment-Pflicht (TTT-Phase 3) | P17: ISB, GL, Hubertus Linz, Günther P., Hannes P. P. Göttling | Q17: Alle | R17: Hoch | S17: Offen | T17: 46172 | W17: 1
A18: F-004 | B18: Information Security | C18: IS Policies and Organization | D18: 1.2.3 | E18: To what extent are information security requirements considered in projects? | F18: Inwieweit werden Anforderungen an Informationssicherheit in Projekten berücksichtigt? | I18: 2 | J18: 3 | K18: =IF(AND(ISNUMBER(I18),ISNUMBER(J18)),J18-I18,"") -> 1 | M18: Umsetzungsgegenstand: Konsolidierung der Maßnahmen aus F-003/1.2.2 zu einer durchgängigen Projekt-IS-Vorgabe als zentraler AL3-Schwerpunkt gem. Stage-Review-Erwartung (20.04.26). Prozessbezug: VDA ISA 1.2.3; ISO 27001 A.5.8; OEM-Prototype-Protection. Workflow Items: 1. Übernahme F-003/Row 17 in dieses Finding. 2. Erweiterung um Engineering (PLM) und Procurement (Supply Chain). 3. Anbindung an ISRA für Projekt-Risikoeintrag. Nachweis: identisch zu F-003/Row 17 + Projekt-Risikoeintrag im ISRA. Abhängigkeiten (Detail s. Spalte N): → Konsolidierung; baut auf F-003 (Major NC) | N18: Vorgelagert: - Row 17 / F-003 / 1.2.2 (IS in Projekten — Major NC) - Row 7 / F-001 / 1.1.1 (Doku-Lenkung) Nachgelagert: - Row 21 / F-005 / 1.2.4 (SLA/OLA) - Row 56 / F-038 / 5.3.1 (IS in neuen Systemen) Querverweise: - Row 28 / F-010 / 1.4.1 (Risiko-Mgmt) | O18: Policy Framework: - Konsolidierte RL 'IS im Projekt- & Produktlebenszyklus' - Übergreifende Projekt-IS-Checkliste (Phase Initiation/Plan/Execute/Close) Standards: - ISO/IEC 27001:2022 A.5.8 - VDA ISA 6.0.3 Kap. 1.2.3 - PMI/IPMA-Projektmgmt-Standards mit IS-Add-on Weitere Empfehlungen: - Konsolidierung redundanter Projekt-Doku in einem Master-Dokument - Projektlistung mit IS-Risikoeinstufung als ISMS-Eingangsdokument | P18: ISB | Q18: Alle | R18: Hoch | S18: Offen | T18: 46142 | W18: 1
A19: F-General | B19: Information Security | C19: IS Policies and Organization | D19: 1.2.4 | E19: To what extent are the responsibilities between external IT service providers and the own organization defined? | F19: Inwieweit sind die Verantwortlichkeiten zwischen externen IT-Dienstleistern und der eigenen Organisation definiert? | G19: Observation | H19: Should = Must Requirements bis auf Diskurs für Nachweis, dass nicht applicable. | I19: 1 | J19: 3 | K19: =IF(AND(ISNUMBER(I19),ISNUMBER(J19)),J19-I19,"") -> 2 | L19: Wir müssen neben den High und Very High Availability Anforderungen immer die Must & Should Anforderungen mit Berücksichtigen. Es gibt die Möglichkeit Should Anforderungen wenn nicht applicable, wegzudiskutieren, dass ist aber kaum möglich! | M19: Umsetzungsgegenstand: Strikte Behandlung aller 'Should'-Anforderungen als faktisch verpflichtend; Ausnahmen nur mit dokumentierter Risikoabwägung und ISB-Approval. Prozessbezug: VDA ISA 1.2.4 (Service-Provider) – übergreifende Methodik; ISO 27001 Clause 6.1.3 (SoA). Workflow Items: 1. SoA-Eintrag pro 'Should'-Ausnahme inkl. Risikoreferenz. 2. ISB-Freigabe vor Auditeintragung. Nachweis: SoA, ISRA-Eintrag, Approval-Workflow im BOS. Abhängigkeiten (Detail s. Spalte N): → methodisch; betrifft Auslegung ALLER Should-Controls | N19: Vorgelagert: - keine (methodischer Hinweis) Nachgelagert: - ALLE 'Should'-Findings (Nachweispflicht statt Optionalität) Querverweise: - Row 4 / F-General (AL3-Niveau) - Row 20 / F-General (Doku-Priorität) | O19: Policy Framework: - ISMS-Maturity-Strategie: 'Should = Must' für AL3 dokumentieren Standards: - VDA ISA 6.0.3 (Maturity-Argumentation) - ENX AL3-Leitfaden Weitere Empfehlungen: - Auditor-Frühabstimmung zur 'Should'-Auslegung - Im SoA: für 'Should'-Controls Nachweis-Strategie hinterlegen | P19: All | Q19: Alle | R19: Hoch | S19: Offen | T19: 46142 | W19: 1
A20: F-General | B20: Information Security | C20: IS Policies and Organization | D20: 1.2.4 | E20: To what extent are the responsibilities between external IT service providers and the own organization defined? | F20: Inwieweit sind die Verantwortlichkeiten zwischen externen IT-Dienstleistern und der eigenen Organisation definiert? | G20: Observation | H20: ENX -> Dokumentierte Umsetzung wichtiger als Policies (!) / e.g.: Wiederherstellung zeigen ! | I20: 1 | J20: 3 | K20: =IF(AND(ISNUMBER(I20),ISNUMBER(J20)),J20-I20,"") -> 2 | L20: Die Etablierung der Verfahren und der Nachweis der Umsetzungen ist wichtiger als die Evidenz der Verfügbarkeit des Policy Frameworks ! | M20: Umsetzungsgegenstand: Verschiebung des Nachweisschwerpunkts von der reinen Policy-Verfügbarkeit hin zu Verfahren und Wirksamkeitsnachweisen (Recovery-Demo, Onboarding-Walkthrough, Incident-Drill). Prozessbezug: VDA ISA AL3-Reifegradlogik; ENX-Audit-Erwartung; ISO 27001 Clause 9.1. Workflow Items: 1. Mapping Policy → Verfahren → Nachweis je Kontrolle (Owner: ISB). 2. Aufbau Evidence-Repository (TISAX-Auditfile) je Kontrolle. 3. Demo-Termine für ausgewählte Verfahren (Recovery, Incident, Onboarding). Nachweis: Evidence-Repository, Demo-Protokolle. Abhängigkeiten (Detail s. Spalte N): → methodisch; betrifft Audit-Nachweisstrategie aller Findings | N20: Vorgelagert: - keine (methodischer Hinweis ENX) Nachgelagert: - ALLE Findings (Umsetzungsnachweis vor Policy-Doku) Querverweise: - Row 19 / F-General (Should=Must) | O20: Policy Framework: - Verschiebung des Doku-Schwerpunkts: Verfahrensanweisungen + Nachweise > reine Policies Standards: - ENX VDA ISA 6.0.3 Auditmethodik - ISO/IEC 27001:2022 §7.5 (Dokumentierte Information als Nachweis) Weitere Empfehlungen: - Auditfile-Struktur: pro Control 1 Policy + N Nachweise (Screenshots, Tickets, Protokolle) - ISB-Audit-File 'Wirksamkeit' als zentraler Folder | P20: All | Q20: Alle | R20: Hoch | S20: Offen | T20: 46142 | W20: 1
A21: F-005 | B21: Information Security | C21: IS Policies and Organization | D21: 1.2.4 | E21: To what extent are the responsibilities between external IT service providers and the own organization defined? | F21: Inwieweit sind die Verantwortlichkeiten zwischen externen IT-Dienstleistern und der eigenen Organisation definiert? | G21: Major NC | H21: Welche internen OLAs existieren und sind vereinbart, welche OT SLAs sind in Verträgen vereinbart und mit dem Mgmt. abgestimmt? Training und lfd. Prozess für OLA und SLA Mgmt. inkl. KPI Darstellung. | I21: 1 | J21: 3 | K21: =IF(AND(ISNUMBER(I21),ISNUMBER(J21)),J21-I21,"") -> 2 | L21: IT & OT Service Provider; Verträge für SK/PL betrachten und erörtern; (SPS Ausfall und vertragliche Vereinbarung), MTO/RTP/RTO Anforderungen an OT, ext. Zugriff und Authentifizierung. Personalisierte Accounts vom ext. Serv. Provider. SLA und OLA für OT- Wo sind die, wer prüft das, welche SLA Agreements sind mit den Externen getroffen. Gleiches gilt für PLM oder AX in Polen. MAximal tolerierte Ausfallzeiten, sind diese definiert und matcht das mit den Verträgen Sinn und wenn nicht ist das Risiko bewertet | M21: Umsetzungsgegenstand: Erfassung und Bewertung aller internen OLAs und externen SLAs für IT- und OT-Dienste (SPS-Wartung, PLM, AX-Polen) inkl. RTO/RPO und personalisierter Accounts externer Dienstleister. Prozessbezug: VDA ISA 1.2.4 + 5.2.8 (Kontinuität); ISO 27001 A.5.19–A.5.23. Workflow Items: 1. SLA/OLA-Register (Owner: IT-Leitung + Plant Manager + ISB). 2. Bewertung Maximum-Tolerable-Outage vs. Vertragslage; ISRA-Eintrag bei Lücken. 3. Personalisierte Service-Provider-Accounts (kein Shared-Access). 4. KPI-Reporting SLA-Einhaltung. Nachweis: SLA/OLA-Register, ISRA, KPI-Report. Abhängigkeiten (Detail s. Spalte N): → Major NC; baut auf F-003/F-006/F-004 | N21: Vorgelagert: - Row 13 / F-003 / 1.2.2 (OT-Verantwortlichkeiten) - Row 23 / F-006 / 1.3.1 (Asset Mgmt) - Row 18 / F-004 / 1.2.3 (IS in Projekten) Nachgelagert: - Row 22 / F-005 / 1.2.4 (externe OT-Zugriffe) - Row 57 / F-039 / 5.3.2 (Netzwerk-SLA) - Row 60 / F-042 / 6.1.1 (Supplier-Mgmt) Querverweise: - Row 15 / F-003 / 1.2.2 (OT-Verträge) | O21: Policy Framework: - OLA-Master für IT-interne Dienste - OLA IT ↔ OT mit Service-Verfügbarkeiten je Anlage/Werk - SLA-Vorlage für externe Wartungspartner Standards: - ISO/IEC 27001:2022 A.5.19-A.5.23 - ITIL 4 Service Level Management - IEC 62443-2-4 (Anforderungen an Service-Provider) - VDA ISA 6.0.3 Kap. 1.2.4 Weitere Empfehlungen: - Major NC: OLA IT/OT für alle 4 Standorte schriftlich (Pflicht für AL3) - Eskalationsmatrix bei OLA-Verletzung (CIO/CFO) - Quartals-Review OLA-Erfüllung als ISMS-KPI | P21: All | Q21: Alle | R21: Hoch | S21: Offen | T21: 46142 | W21: 1
A22: F-005 | B22: Information Security | C22: IS Policies and Organization | D22: 1.2.4 | E22: To what extent are the responsibilities between external IT service providers and the own organization defined? | F22: Inwieweit sind die Verantwortlichkeiten zwischen externen IT-Dienstleistern und der eigenen Organisation definiert? | G22: Minor NC | H22: Fehlener Prozess für Dokumentation von externen Zugriffsszenarien (wer, wie, wielange, worauf, encr. Meth.) im OT Bereich. | I22: 1 | J22: 3 | K22: =IF(AND(ISNUMBER(I22),ISNUMBER(J22)),J22-I22,"") -> 2 | L22: Wie wird das mit externen Service Providern u. Vertragshaltern umgesetzt, wer greift zu, was darf er, wie lange darf er und wie sieht der Request und die Umsetzung aus. Wie wird der Zugriff dokumentiert, so dass es auch eine Historie gibt. Personalisierte Accounts vom ext. Serv. Provider sind nur erlaubt. | M22: Umsetzungsgegenstand: Prozess für Dokumentation externer OT-Zugriffe (Wer / Worauf / Wie lange / Welche Verschlüsselung) mit historischer Nachvollziehbarkeit. Prozessbezug: VDA ISA 1.2.4 + 4.2.1 (Zugriffsrechte); ISO 27001 A.8.2/A.8.5; IEC 62443-3-3 SR 1.1. Workflow Items: 1. STD 'Remote Access OT' (Owner: ISB + OT-Lead). 2. Jump-Host/Bastion-Konzept mit Session-Recording. 3. Approval-Workflow pro Zugriff (max. Gültigkeitsdauer). 4. Audit-Trail-Reporting. Nachweis: STD, Logs-Stichprobe, Approval-Tickets. Abhängigkeiten (Detail s. Spalte N): → baut auf F-005/F-003; treibt F-025/F-026/F-042 | N22: Vorgelagert: - Row 21 / F-005 / 1.2.4 (OLA) - Row 15 / F-003 / 1.2.2 (OT-Verträge) Nachgelagert: - Row 43 / F-025 / 4.1.3 (Account-Mgmt EXT) - Row 44 / F-026 / 4.2.1 (PAM/JIT für externe) - Row 60 / F-042 / 6.1.1 (Supplier) Querverweise: - Row 50 / F-032 / 5.2.4 (Logging externer Zugriffe) | O22: Policy Framework: - Verfahrensanweisung 'Externe Zugriffe' (IT/OT) inkl. Approval-Workflow - Vendor-Access-Request-Formular - Zeitlich befristete Zugänge (JIT) als Default Standards: - ISO/IEC 27001:2022 A.8.2, A.8.3, A.8.18 - IEC 62443-3-3 SR 2.1 / SR 2.2 (Access Control für OT) - VDA ISA 6.0.3 Kap. 1.2.4 / 4.x Weitere Empfehlungen: - PAM-Tool für externe OT-Wartung (z. B. CyberArk, BeyondTrust) - Session-Recording als Pflicht-Logging - Quartals-Audit externe Konten (Stale-Account-Detektion) | P22: All | Q22: Alle | R22: Hoch | S22: Offen | T22: 46142 | W22: 1
A23: F-006 | B23: Information Security | C23: IS Policies and Organization | D23: 1.3.1 | E23: To what extent are information assets identified and recorded? | F23: Inwieweit werden Informationsressourcen erfasst und dokumentiert? | G23: Minor NC | H23: Überprüfung: Sind die Netzwerkdevices im Matrix42 erfasst? Erfassung der OT Devices neben Matrix42 in den gen. Listen für SK und PL (Erweiterung um IP Comm.) | J23: 4 | K23: =IF(AND(ISNUMBER(I23),ISNUMBER(J23)),J23-I23,"") | L23: Beim Asset Mgmt.: Storages und Server bzw. windows devices sollten klar sein. OT Assests kommen in die Liste aber wie sieht es mit Software oder Dokumenten oder Backups oder Finanzdaten als Assests aus, auch diese müssen geführt werden. Rücksprache mit GL bzgl. besondere Finance-Assets als auch andere Assets. Welche weiteren Assetzuordnungen existieren noch? Welche Assets verlässt das unternehmen. Beispiel: Backups die in der cloud sind. Vorschlag: Anpassung Policy für Prozess und Klassifizierung (jährlich) für "besondere" Assets. Prüferfrage "beliebt": End2end Check in Matrix42 für Asset | M23: Umsetzungsgegenstand: Erweiterung des Asset Managements über klassische IT-Assets hinaus auf OT-Devices, Software, Dokumente, Backups, Finanzdaten und Cloud-resident Assets; jährlicher Klassifizierungs-Review. Prozessbezug: VDA ISA 1.3.1; ISO 27001 A.5.9. Workflow Items: 1. Asset-Klassifizierungsschema (Owner: ISB): IT-HW, OT-HW, SW, Daten, Dokumente, Finanzdaten, Cloud-Assets. 2. Anpassung Asset-Mgmt-Policy: jährlicher Review, 'besondere' Assets (Finance, Backups). 3. End-to-End-Test in Matrix42 (Auditor-Standardfrage). Nachweis: Asset-Register vollständig, Klassifizierungsbericht, Matrix42-Audit-Trail. Abhängigkeiten (Detail s. Spalte N): → Fundament: Voraussetzung für F-003, F-007, F-010, F-027, F-033 | N23: Vorgelagert: - keine (Fundamentbaustein) Nachgelagert: - Row 14 / F-003 / 1.2.2 (OT-Assetliste) - Row 24 / F-007 / 1.3.2 (Private Geräte) - Row 28 / F-010 / 1.4.1 (Risiko-Mgmt: Assets als Schutzobjekt) - Row 45 / F-027 / 5.1.1 (Crypto: Assets benötigen Klassifikation) - Row 51 / F-033 / 5.2.5 (Vulnerability Mgmt) - Row 53 / F-035 / 5.2.7 (Netzwerk-Doku) - Row 55 / F-037 / 5.2.9 (Backup-Scope) Querverweise: - Row 49 / F-031 / 5.2.3 (Malware-Schutz-Scope) | O23: Policy Framework: - RL Asset Management (IT + OT + Information) - CMDB-Pflege-Verfahren (Matrix42) inkl. OT-Discovery-Integration Standards: - ISO/IEC 27001:2022 A.5.9-A.5.10 - ISO/IEC 19770 (IT Asset Management) - IEC 62443-2-1 §SP.04 - VDA ISA 6.0.3 Kap. 1.3.1 Weitere Empfehlungen: - Vollständigkeitsprüfung: Netzwerkdevices, IoT, OT-Anlagen, mobile Geräte - Asset-Ownership pro Standort eindeutig zuweisen - Asset-Liste als Eingangsgröße für Risk Register | P23: All | Q23: Alle | R23: Hoch | S23: Offen | T23: 46142 | W23: 1
A24: F-007 | B24: Information Security | C24: IS Policies and Organization | D24: 1.3.2 | E24: To what extent are information assets classified and managed in terms of their protection needs? | F24: Inwieweit werden Informationsressourcen entsprechend ihren Schutzanforderungen klassifiziert und verwaltet? | G24: Major NC | H24: Zugriff von nicht-unternehmens Endgeräten auf Unternehmensdaten aktuell gegeben. Diskurs: Abschalten oderRisikobewertung. Policy Vorgaben Siehe auch die novierte Legacy Policy (PG) mit der Anleitung. Word to PDF, Google Translate, Deepl.com etc. | I24: 2 | J24: 3 | K24: =IF(AND(ISNUMBER(I24),ISNUMBER(J24)),J24-I24,"") -> 1 | L24: Kein Zugriff von privaten Geräten auf Unternehmensinfrastruktur Asset Mgmt. Policy oder Bezug auf Unternehmensgeräte anpassen: 6.5 Speicherung, Transport, Remote Access und Cloud (eMail, Teams, OneDrive - Austausch von Daten). HomeOffice -> Printer usage (TBD); Risikobewertung -> Monitoring/Logging mit Maßnahmenplan organisatorische Maßnahme (Verbot und Verfahrensanweisung)/ eMail-Versandt (!) Konkretisierung von nicht Unternehmensgeräten Vertrauliche Daten dürfen nur auf Firmengeräte das ist bei uns nicht gegeben. Webzugang zu MS Zuhause drucken abschalten- Risiko bewerten in Bezug auf die vertraulichkeit die geschützt werden muss Webmail abschalten wie stellst du sicher das keine online umwandlung oder translation von informationen stattfindet ( als beispiel für daten die das unterehmen verlassen) | M24: Umsetzungsgegenstand: Unterbindung des Zugriffs nicht registrierter (privater) Endgeräte auf Unternehmensdaten; technische Durchsetzung über Conditional Access, DLP-Regeln gegen Cloud-Konverter/-Translate und Web-Mail-Sperre extern. Prozessbezug: VDA ISA 1.3.2 + 3.1.4 + 4.1.2; ISO 27001 A.6.7, A.8.1, A.8.20. Workflow Items: 1. Asset-Mgmt-Policy Kap. 6.5 ergänzen (Storage, Transport, Remote Access, Cloud). 2. Conditional Access 'Compliant Device' aktivieren. 3. DLP-Regeln gegen Upload zu Online-Translate/-Convert. 4. Drucken im Home-Office deaktivieren bzw. risikobewerten. 5. Verbots-Verfahrensanweisung + Monitoring. Nachweis: RL, CA-Policy-Export, DLP-Reports, Verfahrensanweisung freigegeben. Abhängigkeiten (Detail s. Spalte N): → Major NC; baut auf F-006/F-022; treibt F-019/F-024 | N24: Vorgelagert: - Row 23 / F-006 / 1.3.1 (Asset Mgmt) - Row 40 / F-022 / 3.1.4 (Mobile Geräte) Nachgelagert: - Row 37 / F-019 / 2.1.4 (Remote Work) - Row 42 / F-024 / 4.1.2 (MFA) Querverweise: - Row 9 / F-001 / 1.1.1 (Klassifizierung 'Intern') | O24: Policy Framework: - RL BYOD / Private Endgeräte (Verbot oder MDM-Container) - Acceptable-Use-Policy mit klarer Trennung Privat/Unternehmen - Betriebsvereinbarung mit Betriebsrat (mehrsprachig) Standards: - ISO/IEC 27001:2022 A.8.1 - ISO/IEC 27031, ISO/IEC 27033 (Netzwerksicherheit) - VDA ISA 6.0.3 Kap. 1.3.2 Regulatorisch: - DSGVO Art. 32 (technisch-organisatorische Maßnahmen) Weitere Empfehlungen: - Major NC: technische Durchsetzung via Conditional Access (M365) + MDM - Awareness: Phishing-Kampagnen + TTT-Phase 2 zu BYOD-Risiken - Stichprobe-Audit private Geräte-Zugriffe in Logs | P24: All | Q24: Alle | R24: Hoch | S24: Offen | T24: 46142 | W24: 1
A25: F-008 | B25: Information Security | C25: IS Policies and Organization | D25: 1.3.3 | E25: To what extent is it ensured that only evaluated and approved external IT services are used for processing the organization’s information assets? | F25: Inwieweit wird sichergestellt, dass nur evaluierte und genehmigte externe IT-Dienste zur Verarbeitung der Informationsressourcen der Organisation verwendet werden? | G25: Observation | H25: Fehlende Integration eines Assessment für Inf.Sich. Risikobewertung inkl. CIA von externen IT-Providern und dem Zugang/Zutritt auf interne IT-Infr.; gleiches für SW. Vorgaben existieren für verschiedenste Szenarien -> zusammenfassen und in die Vorgaben integrieren. | I25: 2 | J25: 3 | K25: =IF(AND(ISNUMBER(I25),ISNUMBER(J25)),J25-I25,"") -> 1 | L25: Wenn PC nicht geht dann ticket. -> Wenn Machinine nicht geht dann? Wenn intern das problem nicht behoben werden kann, wer entscheidet und ist verantwortlich für externe unterstützung und gibt es eine liste an externen freigegebenen Partnern und der damit einhergehenden Kritierien. Das gleiche gilt für Freigebene Softwarelösungen- Wer darf wen bei was kontaktieren und wo steht es? | M25: Umsetzungsgegenstand: Integration eines verbindlichen IS-/CIA-Risikoassessments für externe IT-Provider, IT-Dienste und Software vor Beauftragung; Konsolidierung bestehender Vorgaben in einem einheitlichen Standard. Prozessbezug: VDA ISA 1.3.3; ISO 27001 A.5.19, A.5.21, A.5.23. Workflow Items: 1. STD 'External IT Service Assessment' (Owner: ISB). 2. Liste freigegebener Partner inkl. Auswahl-Kriterien. 3. Approval-Workflow für Notfall-Beauftragung (Maschinenausfall) mit Eskalationspfad. 4. Aufnahme bestehendes SaaS-Assessment-Toolset (M. Lütz). Nachweis: STD, Freigabeliste, Assessment-Berichte, ISRA-Verknüpfung. Abhängigkeiten (Detail s. Spalte N): → baut auf F-006; treibt F-040/F-041/F-039 | N25: Vorgelagert: - Row 23 / F-006 / 1.3.1 (Asset Mgmt — externe Services als Asset) Nachgelagert: - Row 58 / F-040 / 5.3.3 (Cloud-Disposal) - Row 59 / F-041 / 5.3.4 (Mandantentrennung) - Row 57 / F-039 / 5.3.2 (Netzwerk-SLA) Querverweise: - Row 15 / F-003 / 1.2.2 (OT-Lieferanten) - Row 60 / F-042 / 6.1.1 (Supplier-Mgmt) | O25: Policy Framework: - RL Cloud & Outsourcing-Sicherheit - Cloud-Assessment-Tool (Reutter-intern, M. Lütz) als Pflicht-Eingangs-Tor - Vendor-Risk-Scorecard Standards: - ISO/IEC 27017 (Cloud-Sicherheit) - ISO/IEC 27018 (PII in Cloud) - BSI C5:2020 (Cloud Computing Compliance) - VDA ISA 6.0.3 Kap. 1.3.3 / 5.3.x Weitere Empfehlungen: - Bestehende SaaS-Tools (M365, Sophos, Matrix42) erneut assessen - 'Schatten-IT'-Discovery (CASB / M365 Cloud App Discovery) - Datenklassifikations-Mapping je Cloud-Tool | P25: All | Q25: Alle | R25: Hoch | S25: Offen | T25: 46142 | W25: 1
A26: F-009 | B26: Information Security | C26: IS Policies and Organization | D26: 1.3.4 | E26: To what extent is it ensured that only evaluated and approved software is used for processing the organization’s information assets? | F26: Inwieweit wird sichergestellt, dass nur geprüfte und genehmigte Software zur Verarbeitung der Informationsressourcen der Organisation verwendet wird? | G26: Minor NC | H26: Fehlender Review und Prozess für freigegeben SW. Keine Nachweise wie OT Maintenance im Wartungszyklus bewertet für neue SW und oder zusätzlicher SW. | I26: 2 | J26: 3 | K26: =IF(AND(ISNUMBER(I26),ISNUMBER(J26)),J26-I26,"") -> 1 | L26: Zyklischer Review der bereits freigegeben SW im Bezug auf IT- oder SW-Ownership und Rückfragen, ob in dieser Form noch genutzt oder nicht, wer ist hier der Reviewer? Aufbau Liste für PDCA und Prozess für Tracking/Review und Entscheidung. OT nachprüfen für Prozesse bei OT-DL Querschnittsfunktionen, e.g. wie wird sichergestellt, dass während Maintenance (Wartungszyklus) keine zusätzliche SW installiert wird. | M26: Umsetzungsgegenstand: Zyklischer Review freigegebener Software inkl. SW-Owner, Nutzungsstatus, Aktualität; Verfahren zur Kontrolle der Wartungsfenster im OT-Bereich gegen unautorisierte SW-Installation. Prozessbezug: VDA ISA 1.3.4 + 5.2.1 + 5.2.3; ISO 27001 A.8.19, A.8.32. Workflow Items: 1. SW-Liste mit Owner und Review-Datum (Owner: IT-Leitung). 2. PDCA-Review-Zyklus halbjährlich. 3. OT-Wartungsprotokoll mit Vor-/Nach-Wartungs-Konfigurations-abgleich. Nachweis: SW-Liste mit Review-Status, OT-Wartungsprotokolle, Stichproben. Abhängigkeiten (Detail s. Spalte N): → baut auf F-006; treibt F-029/F-033 | N26: Vorgelagert: - Row 23 / F-006 / 1.3.1 (Asset Mgmt — SW als Asset) Nachgelagert: - Row 47 / F-029 / 5.2.1 (Change Mgmt) - Row 51 / F-033 / 5.2.5 (Vulnerability Mgmt) Querverweise: - Row 27 / F-General / 1.3.4 (IEC 62443-Konformität) - Row 49 / F-031 / 5.2.3 (Malware-Schutz) | O26: Policy Framework: - RL Software-Freigabe & Whitelisting - SBOM-Pflicht (Software Bill of Materials) für OT-/Steuerungssoftware Standards: - ISO/IEC 27001:2022 A.8.19, A.8.30 - IEC 62443-4-1 (Secure Product Development Lifecycle) - NIST SSDF (SP 800-218) - VDA ISA 6.0.3 Kap. 1.3.4 Regulatorisch: - EU Cyber Resilience Act (CRA) — Vorbereitung Weitere Empfehlungen: - SW-Freigabe-Workflow in Matrix42 abbilden - AppLocker / WDAC-Pilot in Office-Umgebung - OT-SW-Whitelist je Anlage SK/PL/AT | P26: All | Q26: IT / SK / PL | R26: Hoch | S26: Offen | T26: 46142 | W26: 1
A27: F-General | B27: Information Security | C27: IS Policies and Organization | D27: 1.3.4 | E27: To what extent is it ensured that only evaluated and approved software is used for processing the organization’s information assets? | F27: Inwieweit wird sichergestellt, dass nur geprüfte und genehmigte Software zur Verarbeitung der Informationsressourcen der Organisation verwendet wird? | G27: Observation | H27: Immer darauf achten wenn die ISA/IEC 62443 referenziert wird (in der Spalte P) muss OT mehr Berücksichtigt werden( Security for industrial automation and control systems) | I27: 2 | J27: 3 | K27: 1 | L27: Durchführung Assessment Prüfkatalog wo ISA/IEC 62443 gegeben in Spalte P für den OT Kontext und Prüfung der Konformität für OT. Erstelllung Liste mit entspr. Vorgaben für Maßnahmen und Umsetzungen | M27: Umsetzungsgegenstand: Systematische OT-Konformitätsprüfung aller VDA-ISA-Kontrollen mit IEC-62443-Referenz (Spalte P) und Ableitung OT-spezifischer Umsetzungsmaßnahmen. Prozessbezug: VDA ISA Spalte P (IEC 62443); IEC 62443-2-1/-3-3. Workflow Items: 1. Filter ISA-Excel auf IEC-62443-markierte Kontrollen (Owner: ISB). 2. OT-Gap-Analyse pro Kontrolle. 3. Maßnahmenliste IT/OT-getrennt mit Verknüpfung zu OT-Patch-/VM-Standard. Nachweis: Gap-Analyse-Bericht, Maßnahmenliste, ISRA-Eintrag. Abhängigkeiten (Detail s. Spalte N): → baut auf F-003 (OT-Verantw./Assets); treibt alle OT-5.2.x-Findings | N27: Vorgelagert: - Row 13 / F-003 / 1.2.2 (OT-Verantwortlichkeiten) - Row 14 / F-003 / 1.2.2 (OT-Assetliste) Nachgelagert: - ALLE OT-Findings (5.2.5, 5.2.6, 5.2.7, 5.2.9) - Row 47 / F-029 / 5.2.1 (OT-Change-Mgmt) Querverweise: - Row 26 / F-009 / 1.3.4 (SW-Review) | O27: Policy Framework: - OT-Security-Rahmenrichtlinie (REUTIB) konform IEC 62443 - OT-Architektur-Standards mit Purdue-Modell-Referenz Standards: - IEC 62443-2-1, -3-2, -3-3, -4-1, -4-2 (vollständige Reihe) - ISO/IEC 27019 (Energieversorgung; übertragbar auf Fertigung) - VDA ISA 6.0.3 Kap. 1.3.4 Weitere Empfehlungen: - IEC 62443 als verbindlicher Konformitätsrahmen im SoA verankern - OT-Spezialaudit durch externen IEC-62443-Lead-Auditor (separat zu CIS) - Schulung OT-Lead je Werk in IEC 62443 | P27: ISB | Q27: Alle | R27: Hoch | S27: Offen | T27: 46142 | W27: 1
